Workbook

Sheet Dashboard
A1: MORPHOGENESIS — Custom CoreXY 3D Printer Build
A2: Sean | Whitehorse, YT, Canada · All prices in CAD · Generated: 2026-05-15
A4: Section | B4: Description | C4: Item Count | D4: Total Cost (CAD)
A5: Hardware BOM | B5: Full build bill of materials — frame, motion, electronics, hotend, bed, wiring | C5: ~150 | D5: ='Hardware BOM'!F98
A6: CF Upgrade Kit | B6: Hardened nozzles, all-metal hotend path, dryer, sealed enclosure upgrades | C6: ~20 | D6: ='CF Upgrade Kit'!F42
A7: Supply Checklist | B7: Ongoing consumables, tools, spare parts, adhesion supplies, safety gear | C7: ~45 | D7: ='Supply Checklist'!E64
A8: GRAND TOTAL | B8: Complete Morphogenesis build investment (all sections) | D8: =SUM(D5:D7)
A10: UPGRADE TIER UNLOCK TABLE
A11: Tier | B11: Tier Name | C11: Key Upgrades Required | D11: Materials Unlocked | E11: Estimated Add-On Cost (CAD) | F11: Notes
A12: 1 | B12: Stock Build | C12: None — printer as built | D12: PLA, PLA+, PETG, TPU 95A | E12: $0 | F12: Good for most hobby printing; enclosed helps with PETG.
A13: 2 | B13: Hardened Nozzle | C13: Hardened steel 0.4mm nozzle(s) | D13: PLA-CF, PETG-CF, glow/abrasive PLAs | E13: ~$30–60 | F13: Single biggest upgrade for abrasive filaments.
A14: 3 | B14: Sealed Enclosure | C14: Foam weatherstripping, sealed panels, exhaust fan + activated carbon filter | D14: ABS, ASA (fumes contained) | E14: ~$50–100 | F14: Required for ABS/ASA off-gassing control.
A15: 4 | B15: Dryer + All-Metal Hotend | C15: Filament dryer (Sunlu S2/S4), bi-metal heat break, full metal hotend path | D15: Nylon PA12, Nylon PA12-CF, PAHT-CF | E15: ~$100–200 | F15: Dry filament + no PTFE in hot zone critical for Nylon.
A16: 5 | B16: Heated Chamber | C16: PTC or silicone pad chamber heater + thermocouple + SSR, chamber temp 45–60°C | D16: PC (Polycarbonate), PC-CF | E16: ~$80–150 | F16: Chamber heat reduces PC warping dramatically.
A17: 6 | B17: Industrial / Full Kit | C17: All tiers + Ruby or Nozzle X nozzle, Garolite bed surface, high-flow extruder | D17: All materials including high-temp industrial | E17: ~$300–500 total add-on | F17: Top-spec build capable of any FDM material.
A19: Section | B19: Cost (CAD)
A20: Hardware BOM | B20: ='Hardware BOM'!F98
A21: CF Upgrade Kit | B21: ='CF Upgrade Kit'!F42
A22: Supply Checklist | B22: ='Supply Checklist'!E64

Sheet Hardware BOM
A1: MORPHOGENESIS — Hardware Bill of Materials
A2: Full CoreXY enclosed printer build · ~300×300mm build volume · Klipper / BTT Octopus · All prices CAD
A3: Component Name | B3: Category | C3: Qty | D3: Unit Price (CAD) | E3: Total (CAD) | F3: Supplier | G3: Part # / Search Term | H3: Notes
A4: MGN12H Linear Rail 300mm (X-axis) | B4: Motion System | C4: 1 | D4: 22.5 | E4: =C4*D4 | F4: AliExpress | G4: MGN12H linear rail 300mm | H4: Full length X carriage rail; get extra carriages
A5: MGN12H Linear Rail 350mm (Y-axis L) | B5: Motion System | C5: 1 | D5: 24 | E5: =C5*D5 | F5: AliExpress | G5: MGN12H linear rail 350mm | H5: Left Y rail
A6: MGN12H Linear Rail 350mm (Y-axis R) | B6: Motion System | C6: 1 | D6: 24 | E6: =C6*D6 | F6: AliExpress | G6: MGN12H linear rail 350mm | H6: Right Y rail
A7: MGN9H Linear Rail 300mm (Z-axis) | B7: Motion System | C7: 3 | D7: 18 | E7: =C7*D7 | F7: AliExpress | G7: MGN9H linear rail 300mm | H7: 3 rails for triple-Z or single Z
A8: MGN12H Carriage Block (extra) | B8: Motion System | C8: 2 | D8: 8.5 | E8: =C8*D8 | F8: AliExpress | G8: MGN12H carriage block | H8: Spare carriage blocks
A9: GT2 6mm Open-Loop Belt 5m | B9: Motion System | C9: 1 | D9: 14 | E9: =C9*D9 | F9: Amazon.ca | G9: GT2 6mm open loop belt 5m | H9: CoreXY XY motion belt
A10: GT2 Idler Pulley 20T (toothed) | B10: Motion System | C10: 4 | D10: 3.5 | E10: =C10*D10 | F10: AliExpress | G10: GT2 20T toothed idler 5mm bore | H10: Toothed idlers at belt junctions
A11: GT2 Idler Pulley 20T (smooth) | B11: Motion System | C11: 4 | D11: 3 | E11: =C11*D11 | F11: AliExpress | G11: GT2 20T smooth idler 5mm bore | H11: Smooth idlers for belt routing
A12: GT2 Pulley 16T 5mm bore (motor) | B12: Motion System | C12: 2 | D12: 3.25 | E12: =C12*D12 | F12: AliExpress | G12: GT2 16T pulley 5mm bore | H12: Mounted on XY stepper shafts
A13: Aluminum 2020 V-slot Extrusion 400mm | B13: Frame | C13: 4 | D13: 5.5 | E13: =C13*D13 | F13: Amazon.ca | G13: 2020 V-slot aluminum extrusion 400mm | H13: Top/bottom frame members
A14: Aluminum 2020 V-slot Extrusion 350mm | B14: Frame | C14: 4 | D14: 5 | E14: =C14*D14 | F14: Amazon.ca | G14: 2020 V-slot aluminum extrusion 350mm | H14: Side verticals
A15: Aluminum 2040 V-slot Extrusion 400mm | B15: Frame | C15: 2 | D15: 9 | E15: =C15*D15 | F15: Amazon.ca | G15: 2040 V-slot aluminum extrusion 400mm | H15: Gantry cross members
... A72: M3 Socket Head Cap Screw 10mm (100pk) | B72: Fasteners | C72: 1 | D72: 7.5 | E72: =C72*D72 | F72: Amazon.ca | G72: M3 SHCS 10mm stainless 100 pack | H72: General M3 fasteners
A73: M3 Socket Head Cap Screw 12mm (100pk) | B73: Fasteners | C73: 1 | D73: 7.5 | E73: =C73*D73 | F73: Amazon.ca | G73: M3 SHCS 12mm stainless 100 pack
A74: M3 Socket Head Cap Screw 16mm (50pk) | B74: Fasteners | C74: 1 | D74: 6 | E74: =C74*D74 | F74: Amazon.ca | G74: M3 SHCS 16mm stainless 50 pack
A75: M3 Socket Head Cap Screw 20mm (50pk) | B75: Fasteners | C75: 1 | D75: 6.5 | E75: =C75*D75 | F75: Amazon.ca | G75: M3 SHCS 20mm stainless 50 pack
A76: M3 Socket Head Cap Screw 25mm (25pk) | B76: Fasteners | C76: 1 | D76: 5.5 | E76: =C76*D76 | F76: Amazon.ca | G76: M3 SHCS 25mm stainless 25 pack
A77: M3 Hex Nut (200 pack) | B77: Fasteners | C77: 1 | D77: 6 | E77: =C77*D77 | F77: Amazon.ca | G77: M3 hex nut stainless 200 pack
A78: M3 Heatset Insert (100pk) | B78: Fasteners | C78: 1 | D78: 12 | E78: =C78*D78 | F78: Amazon.ca | G78: M3 brass heatset insert 3D printing 100pk | H78: For all printed parts joints
A79: M4 Socket Head Cap Screw 8mm (100pk) | B79: Fasteners | C79: 1 | D79: 8 | E79: =C79*D79 | F79: Amazon.ca | G79: M4 SHCS 8mm stainless 100 pack | H79: Frame extrusion fasteners
A80: M5 BHCS 8mm Button Head (50pk) | B80: Fasteners | C80: 1 | D80: 7 | E80: =C80*D80 | F80: Amazon.ca | G80: M5 button head screw 8mm 50 pack | H80: Linear rail to extrusion
A81: M2 Self-Tapping Screw 6mm (100pk) | B81: Fasteners | C81: 1 | D81: 4.5 | E81: =C81*D81 | F81: Amazon.ca | G81: M2 self-tapping screw 6mm 100pk | H81: Electronics board mounts
A82: Spring Washer M3 (100pk) | B82: Fasteners | C82: 1 | D82: 4 | E82: =C82*D82 | F82: Amazon.ca | G82: M3 spring lock washer 100 pack | H82: Belt tension and vibration locking
A83: PTFE Tube 4mm OD 2mm ID 1m | B83: Cables & Wiring | C83: 2 | D83: 8 | E83: =C83*D83 | F83: Amazon.ca | G83: PTFE tube 4mm OD 2mm ID Capricorn | H83: Bowden guide to toolhead sections
A84: Drag Chain Cable 10×10 open 1m | B84: Cables & Wiring | C84: 1 | D84: 16 | E84: =C84*D84 | F84: Amazon.ca | G84: cable drag chain 10x10mm open top 1m | H84: Toolhead umbilical wiring
A85: Silicone Wire 22AWG 5 colors 10m ea | B85: Cables & Wiring | C85: 1 | D85: 32 | E85: =C85*D85 | F85: Amazon.ca | G85: silicone wire 22AWG 10m 5 color set | H85: Main wiring harness; heat-tolerant
A86: Silicone Wire 26AWG 5 colors 5m ea | B86: Cables & Wiring | C86: 1 | D86: 20 | E86: =C86*D86 | F86: Amazon.ca | G86: silicone wire 26AWG 5m 5 color set | H86: Signal wiring (thermistor, endstops)
A87: JST-XH Connector Kit (250pcs) | B87: Cables & Wiring | C87: 1 | D87: 16 | E87: =C87*D87 | F87: Amazon.ca | G87: JST XH connector kit 2 3 4 5 pin 250pcs | H87: Fan, endstop, probe connectors
A88: Molex Micro-Fit 3.0 Connector Kit | B88: Cables & Wiring | C88: 1 | D88: 22 | E88: =C88*D88 | F88: DigiKey CA | G88: Molex 43025 Micro-Fit connector kit | H88: High-current heater/motor connectors
A89: Cable Sleeve 6mm braided 5m | B89: Cables & Wiring | C89: 1 | D89: 10 | E89: =C89*D89 | F89: Amazon.ca | G89: braided cable sleeve 6mm 5m black | H89: Wiring harness protection
... A97: Loctite 243 Threadlocker Blue 5ml | B97: Misc Hardware | C97: 1 | D97: 9 | E97: =C97*D97 | F97: Amazon.ca | G97: Loctite 243 blue threadlocker 5ml | H97: Vibration-resistant fasteners on rails/motors
A98: TOTAL HARDWARE BOM COST | E98: =SUM(E4:E97)
A100: Note: Prices are CAD estimates as of May 2026. Verify current pricing on supplier websites before ordering. AliExpress prices may vary with shipping.

Sheet Filament Guide
A1: MORPHOGENESIS — Filament Reference Guide
A2: Compatible filament types for the Morphogenesis build · 1.75mm · All temps in °C · Prices CAD/kg
A3: Filament Type | B3: Brand Rec. | C3: Diameter (mm) | D3: Spool (kg) | E3: Price/kg (CAD) | F3: Hardware Tier | G3: Nozzle Type | H3: Bed Temp (°C) | I3: Hotend Temp (°C) | J3: Enclosure Req. | K3: Drying Req. | L3: Dry Temp (°C) | M3: Dry Time (hrs) | N3: Notes / Use Cases
A4: PLA | B4: eSUN / Prusament | C4: 1.75 | D4: 1 | E4: 28 | F4: Tier 1 | G4: Brass 0.4mm | H4: 60 | I4: 215 | J4: No | K4: No | N4: General prototyping, decorative prints. Easiest to print. Biodegradable PLA+PBAT blend common.
A5: PLA+ | B5: eSUN PLA+ / Polymaker | C5: 1.75 | D5: 1 | E5: 32 | F5: Tier 1 | G5: Brass 0.4mm | H5: 60 | I5: 225 | J5: No | K5: No | N5: Tougher than standard PLA; better layer adhesion and impact resistance. Still easy to print.
A6: PETG | B6: Prusament / eSUN | C6: 1.75 | D6: 1 | E6: 35 | F6: Tier 1 | G6: Brass 0.4mm | H6: 80 | I6: 240 | J6: Opt | K6: No | N6: Good chemical resistance; slightly flexible. Great for functional parts. Slight moisture sensitivity.
A7: PETG-CF | B7: eSUN PETG-CF / Bambu | C7: 1.75 | D7: 0.5 | E7: 55 | F7: Tier 2 | G7: Hardened Steel 0.4mm | H7: 80 | I7: 245 | J7: Opt | K7: Yes | L7: 65 | M7: 4 | N7: CF-reinforced PETG; stiffer, lighter. Abrasive — brass nozzle wears in hours. Good for brackets/mounts.
A8: ASA | B8: Polymaker PolyLite | C8: 1.75 | D8: 1 | E8: 42 | F8: Tier 3 | G8: Brass 0.4mm | H8: 90 | I8: 245 | J8: Yes | K8: Yes | L8: 60 | M8: 4 | N8: UV-stable, temp-resistant. ABS replacement for outdoor parts. Needs enclosure to prevent warping.
A9: ABS | B9: eSUN ABS+ / Bambu | C9: 1.75 | D9: 1 | E9: 32 | F9: Tier 3 | G9: Brass 0.4mm | H9: 100 | I9: 240 | J9: Yes | K9: Yes | L9: 60 | M9: 4 | N9: Classic functional filament; post-process with acetone smoothing. Enclosure critical.
A10: TPU 95A | B10: eSUN TPU / Polymaker | C10: 1.75 | D10: 0.5 | E10: 45 | F10: Tier 1 | G10: Brass 0.4mm | H10: 40 | I10: 225 | J10: No | K10: Yes | L10: 50 | M10: 4 | N10: Flexible/rubber-like. Good for grips, gaskets, phone cases. Direct drive required; no Bowden.
A11: Nylon PA12 | B11: Polymaker PA12 / Fiberon | C11: 1.75 | D11: 0.5 | E11: 65 | F11: Tier 4 | G11: Hardened Steel 0.4mm | H11: 85 | I11: 260 | J11: Yes | K11: Yes | L11: 80 | M11: 12 | N11: Strong, fatigue-resistant, slightly flexible. Very hygroscopic — dry before and during print. Excellent for gears.
A12: Nylon PA12-CF | B12: Polymaker PA12-CF | C12: 1.75 | D12: 0.5 | E12: 85 | F12: Tier 4 | G12: Hardened Steel 0.4mm | H12: 90 | I12: 260 | J12: Yes | K12: Yes | L12: 80 | M12: 12 | N12: CF-reinforced PA12; high stiffness-to-weight. Demanding on hotend and nozzle. Print slowly.
A13: PC | B13: Polymaker PC-01 / eSUN | C13: 1.75 | D13: 0.5 | E13: 70 | F13: Tier 5 | G13: Hardened Steel 0.4mm | H13: 115 | I13: 280 | J13: Yes | K13: Yes | L13: 80 | M13: 8 | N13: High-impact, transparent possible, heat-resistant to 110°C+. Needs heated chamber ~50°C. Difficult to print.
A14: PC-CF | B14: 3DXTech CarbonX PC-CF | C14: 1.75 | D14: 0.5 | E14: 110 | F14: Tier 6 | G14: Nozzle X / Ruby | H14: 120 | I14: 300 | J14: Yes | K14: Yes | L14: 90 | M14: 8 | N14: Industrial-grade CF+PC composite. Extremely stiff and heat-resistant. Requires Ruby or Nozzle X. Slow print.
A15: PLA-CF | B15: Bambu PLA-CF / eSUN | C15: 1.75 | D15: 0.5 | E15: 52 | F15: Tier 2 | G15: Hardened Steel 0.4mm | H15: 60 | I15: 220 | J15: No | K15: No | N15: CF-filled PLA; stiffer and lighter than standard PLA. Great entry into CF printing with easy settings.
A16: PAHT-CF | B16: 3DXTech PAHT-CF | C16: 1.75 | D16: 0.5 | E16: 130 | F16: Tier 5 | G16: Nozzle X / Ruby | H16: 110 | I16: 300 | J16: Yes | K16: Yes | L16: 90 | M16: 12 | N16: High-temp PA + CF; Tg 180°C+. Extremely demanding — needs everything: dryer, enclosure, heated chamber, metal nozzle.
A18: TIER COLOUR KEY | B18: Red J column = enclosure required · Orange K column = drying required · Red nozzle text = Ruby or Nozzle X required · Green nozzle text = hardened steel required
A19: Tier 1 — No upgrades (PLA/PETG/TPU)
A20: Tier 2 — Hardened Nozzle (PLA-CF, PETG-CF)
A21: Tier 3 — Sealed Enclosure (ABS, ASA)
A22: Tier 4 — Dryer + All-Metal Hotend (Nylon PA12)
A23: Tier 5 — Heated Chamber (PC, PAHT-CF)
A24: Tier 6 — Full Industrial Kit (PC-CF)

Sheet CF Upgrade Kit
A1: MORPHOGENESIS — CF & Abrasive Filament Upgrade Kit
A2: All upgrades to unlock CF, Nylon, PC and abrasive filament printing · Prices in CAD · May 2026
A3: Upgrade Item | B3: Category | C3: Why It’s Needed | D3: Qty | E3: Unit Price (CAD) | F3: Total (CAD) | G3: Supplier | H3: Part # / Search Term | I3: Priority
A4: NOZZLES
A5: E3D Hardened Steel Nozzle 0.4mm (V6) | B5: Nozzles | C5: Brass wears out in hours on CF/abrasive filaments | D5: 3 | E5: 12 | F5: =D5*E5 | G5: Amazon.ca | H5: "E3D hardened steel nozzle 0.4mm V6" | I5: Must Have
A6: Hardened Steel Nozzle 0.6mm | B6: Nozzles | C6: Larger bore reduces CF clogs; better flow | D6: 2 | E6: 12 | F6: =D6*E6 | G6: Amazon.ca | H6: "hardened steel nozzle 0.6mm V6" | I6: Recommended
A7: Hardened Steel Nozzle 0.8mm | B7: Nozzles | C7: Max flow for structural CF infill | D7: 1 | E7: 12 | F7: =D7*E7 | G7: Amazon.ca | H7: "hardened steel nozzle 0.8mm V6" | I7: Nice to Have
A8: E3D Nozzle X 0.4mm | B8: Nozzles | C8: Tungsten carbide; outlasts standard hardened steel 5–10× | D8: 2 | E8: 34 | F8: =D8*E8 | G8: Amazon.ca | H8: "E3D Nozzle X 0.4mm" | I8: Recommended
A9: Olsson Ruby Nozzle 0.4mm | B9: Nozzles | C9: Ruby tip; virtually indestructible; required for PAHT-CF/PC-CF at 300°C+ | D9: 1 | E9: 95 | F9: =D9*E9 | G9: 3DJake.ca | H9: "Olsson Ruby nozzle 0.4mm V6" | I9: Nice to Have
A10: HOTEND PATH
A11: Slice Engineering Copperhead Bi-Metal Heat Break | B11: Hotend Path | C11: Eliminates PTFE from hot zone; required for Nylon/PC above 240°C | D11: 1 | E11: 38 | F11: =D11*E11 | G11: Amazon.ca | H11: "Slice Engineering Copperhead heat break" | I11: Must Have
A12: E3D Titanium Heat Break V6 | B12: Hotend Path | C12: Budget all-metal alternative to Copperhead | D12: 1 | E12: 18 | F12: =D12*E12 | G12: Amazon.ca | H12: "E3D titanium heat break V6" | I12: Recommended
A13: High-Temp Silicone Sock Rapido/Dragon HF (3-pack) | B13: Hotend Path | C13: Insulates heat block; stabilizes temp during high-temp prints | D13: 3 | E13: 5 | F13: =D13*E13 | G13: AliExpress | H13: "silicone sock Rapido HF hotend" | I13: Must Have
A14: EXTRUDER
A15: Hardened Steel BMG/Orbiter Drive Gears | B15: Extruder | C15: Standard brass gears strip on CF within one spool | D15: 1 | E15: 28 | F15: =D15*E15 | G15: Amazon.ca | H15: "hardened steel BMG extruder gears" | I15: Must Have
A16: NEMA 17 55Ncm High-Torque Extruder Motor | B16: Extruder | C16: CF filaments have higher feed resistance | D16: 1 | E16: 22 | F16: =D16*E16 | G16: Amazon.ca | H16: "NEMA 17 stepper 55Ncm extruder" | I16: Recommended
A17: FILAMENT DRYING
A18: Sunlu FilaDryer S2 (2-spool active dryer) | B18: Filament Drying | C18: Nylon/PC/PA-CF must be printed dry; live feed from dryer | D18: 1 | E18: 72 | F18: =D18*E18 | G18: Amazon.ca | H18: "Sunlu FilaDryer S2 filament dryer" | I18: Must Have
A19: Sunlu FilaDryer S4 (4-spool upgrade) | B19: Filament Drying | C19: Keeps 4 spools dry simultaneously for multi-material workflows | D19: 1 | E19: 95 | F19: =D19*E19 | G19: Amazon.ca | H19: "Sunlu FilaDryer S4 4 spool" | I19: Recommended
A20: eSUN eBOX Plus Dryer/Feeder with Scale | B20: Filament Drying | C20: Alternative dryer with built-in weight scale | D20: 1 | E20: 68 | F20: =D20*E20 | G20: Amazon.ca | H20: "eSUN eBOX Plus filament dryer" | I20: Nice to Have
A21: Silica Gel 500g Orange Indicating (×3 bags) | B21: Filament Drying | C21: Absorbs moisture in storage; rechargeable | D21: 3 | E21: 14 | F21: =D21*E21 | G21: Amazon.ca | H21: "silica gel 500g orange indicating" | I21: Must Have
A22: Vacuum Seal Bags + Hand Pump 10-pack | B22: Filament Drying | C22: Vacuum sealing keeps opened spools bone-dry | D22: 1 | E22: 18 | F22: =D22*E22 | G22: Amazon.ca | H22: "vacuum seal storage bags 10 pack pump" | I22: Recommended
A23: Iris USA Airtight Container 12qt (×4) | B23: Filament Drying | C23: Rigid airtight dry storage; 1 spool per container + silica | D23: 4 | E23: 16 | F23: =D23*E23 | G23: Amazon.ca | H23: "Iris USA 12qt airtight storage container" | I23: Recommended
A24: ENCLOSURE & FUME CONTROL
A25: Foam Weatherstrip Tape 6mm×3mm Self-Adhesive 5m (×2) | B25: Enclosure | C25: Seals panel gaps; retains heat; contains ABS/ASA/Nylon fumes | D25: 2 | E25: 8 | F25: =D25*E25 | G25: Amazon.ca | H25: "foam weatherstrip tape self-adhesive 6mm 3mm 5m" | I25: Must Have
A26: 60mm Exhaust Fan 24V | B26: Enclosure | C26: Vents chamber fumes through filter; run during ABS/ASA/Nylon | D26: 1 | E26: 12 | F26: =D26*E26 | G26: Amazon.ca | H26: "60mm fan 24V exhaust 3D printer" | I26: Must Have
A27: Activated Carbon + HEPA Filter Module 60mm | B27: Enclosure | C27: Removes VOCs and particulates from exhaust | D27: 1 | E27: 22 | F27: =D27*E27 | G27: Amazon.ca | H27: "60mm activated carbon HEPA filter 3D printer" | I27: Must Have
A28: Nevermore Micro V5 Recirculating Carbon Filter | B28: Enclosure | C28: Recirculates chamber air through carbon; reduces internal VOC buildup | D28: 1 | E28: 45 | F28: =D28*E28 | G28: Amazon.ca | H28: "Nevermore Micro V5 carbon filter" | I28: Recommended
A29: CHAMBER HEATING (Tier 5 — Unlocks PC / PAHT-CF)
A30: PTC Ceramic Chamber Heater 220V 200W | B30: Chamber Heating | C30: Raises chamber to 45–60°C; eliminates PC warping | D30: 1 | E30: 28 | F30: =D30*E30 | G30: Amazon.ca | H30: "PTC ceramic heater 220V 200W 3D printer chamber" | I30: Recommended
A31: Solid State Relay SSR-25DA (chamber heater control) | B31: Chamber Heating | C31: Klipper switches 220V chamber heater via temp PID | D31: 1 | E31: 14 | F31: =D31*E31 | G31: Amazon.ca | H31: "SSR-25DA solid state relay 25A" | I31: Recommended
A32: NTC 100K Thermistor Chamber Sensor (×2) | B32: Chamber Heating | C32: Closed-loop Klipper chamber temp control | D32: 2 | E32: 6 | F32: =D32*E32 | G32: Amazon.ca | H32: "NTC 100K thermistor 3D printer chamber" | I32: Recommended
A33: BED SURFACES FOR CF / NYLON / PC
A34: Garolite G10 Sheet 300×300mm 1.5mm | B34: Bed Surfaces | C34: Best Nylon adhesion surface; releases cleanly when cool | D34: 1 | E34: 38 | F34: =D34*E34 | G34: Amazon.ca | H34: "Garolite G10 sheet 300x300mm 1.5mm" | I34: Recommended
A35: Elmer’s Purple Glue Stick 12-pack | B35: Bed Surfaces | C35: Release agent for PC on PEI; prevents sheet delamination | D35: 1 | E35: 8 | F35: =D35*E35 | G35: Amazon.ca | H35: "Elmer's purple glue stick school glue" | I35: Must Have
A36: NOZZLE MAINTENANCE
A37: Brass Wire Nozzle Cleaning Brush (×2) | B37: Maintenance | C37: Removes CF char from nozzle tip without damaging geometry | D37: 2 | E37: 7 | F37: =D37*E37 | G37: Amazon.ca | H37: "brass wire brush nozzle cleaning 3D printer" | I37: Must Have
A38: Nozzle Cleaning Needle Set 0.3/0.4/0.5mm 10pcs | B38: Maintenance | C38: Clears partial clogs; insert at 200°C before cold pull | D38: 1 | E38: 9 | F38: =D38*E38 | G38: Amazon.ca | H38: "nozzle cleaning needle 0.4mm 10 pack" | I38: Must Have
A39: Natural Nylon Filament 1.75mm 100g (cold pull) | B39: Maintenance | C39: Best cold pull medium for clearing CF char from hotend | D39: 1 | E39: 15 | F39: =D39*E39 | G39: Amazon.ca | H39: "natural Nylon 1.75mm 100g cold pull filament" | I39: Recommended
A40: Capricorn XS PTFE Tube 1.75mm 1m | B40: Maintenance | C40: Tighter 1.9mm ID for feed-path section before extruder | D40: 1 | E40: 16 | F40: =D40*E40 | G40: Amazon.ca | H40: "Capricorn XS PTFE tube 1.75mm 1m" | I40: Recommended
...

Sheet Supply Checklist
A1: MORPHOGENESIS — Ongoing Printer Supply Checklist
A2: Consumables, tools, safety gear, and spare parts · Reorder frequencies assume ~20hrs/week print volume · Prices in CAD
A3: Item | B3: Category | C3: Qty to Stock | D3: Unit Price (CAD) | E3: Total (CAD) | F3: Reorder Frequency | G3: Supplier | H3: Notes
A4: ADHESION SUPPLIES
A5: Magigoo Original Adhesive Stick | B5: Adhesion | C5: 2 | D5: 18 | E5: =C5*D5 | F5: Every 6 months | G5: Amazon.ca | H5: Apply to warm bed; wipe with warm water; excellent for PLA/PETG/ABS
A6: Magigoo PC Formula | B6: Adhesion | C6: 1 | D6: 22 | E6: =C6*D6 | F6: Every 6–12 months | G6: Amazon.ca | H6: PC-specific formula; far superior to glue stick for polycarbonate
A7: 3DLAC Adhesion Spray 400ml | B7: Adhesion | C7: 1 | D7: 20 | E7: =C7*D7 | F7: Every 4–6 months | G7: Amazon.ca | H7: For ASA and ABS on glass or PEI; lasts many prints per can
A8: Elmer’s Purple Glue Stick 12-pack | B8: Adhesion | C8: 1 | D8: 14 | E8: =C8*D8 | F8: Every 6 months | G8: Amazon.ca | H8: Release agent for PC on PEI; also aids Nylon adhesion on smooth PEI
A9: Isopropyl Alcohol 99% 1L | B9: Adhesion | C9: 2 | D9: 14 | E9: =C9*D9 | F9: Every 3 months | G9: Amazon.ca | H9: Bed cleaning between prints; 99% only — 70% leaves water residue
A10: BED SURFACES
A11: PEI Spring Steel Sheet Smooth 300×300mm (spare) | B11: Bed Surfaces | C11: 1 | D11: 36 | E11: =C11*D11 | F11: Every 12–18 months | G11: Amazon.ca | H11: Replace when scratched or delaminated; rotate with textured sheet
A12: PEI Spring Steel Sheet Textured 300×300mm (spare) | B12: Bed Surfaces | C12: 1 | D12: 38 | E12: =C12*D12 | F12: Every 12–18 months | G12: Amazon.ca | H12: Matte bottom finish; great for PETG/PLA easy removal
A13: Garolite G10 Sheet 300×300mm (spare) | B13: Bed Surfaces | C13: 1 | D13: 38 | E13: =C13*D13 | F13: Every 18–24 months | G13: Amazon.ca | H13: Nylon surface; replace when gouged or adhesion fails
A14: NOZZLE STOCK
A15: Hardened Steel Nozzle 0.4mm 3-pack | B15: Nozzles | C15: 1 | D15: 30 | E15: =C15*D15 | F15: Every 6–12 months | G15: Amazon.ca | H15: CF/abrasive primary nozzle; replace when flow becomes inconsistent
A16: Hardened Steel Nozzle 0.6mm 2-pack | B16: Nozzles | C16: 1 | D16: 22 | E16: =C16*D16 | F16: Every 12 months | G16: Amazon.ca | H16: Structural CF parts at higher flow rate
A17: Brass Nozzle 0.4mm V6 10-pack | B17: Nozzles | C17: 1 | D17: 10 | E17: =C17*D17 | F17: Every 6 months | G17: Amazon.ca | H17: High-volume PLA/PETG use; cheap to replace rather than clean
A18: E3D Nozzle X 0.4mm (spare) | B18: Nozzles | C18: 1 | D18: 34 | E18: =C18*D18 | F18: Every 12–24 months | G18: Amazon.ca | H18: Long-life nozzle; replace when tungsten coating shows tip wear
A19: LUBRICATION & MAINTENANCE
A20: Super Lube 21030 PTFE Grease 3oz | B20: Lubrication | C20: 1 | D20: 14 | E20: =C20*D20 | F20: Every 12 months | G20: Amazon.ca | H20: MGN12H rail carriages; apply sparingly to rail channel; avoid over-greasing
A21: Super Lube 51010 PTFE Oil 4oz | B21: Lubrication | C21: 1 | D21: 12 | E21: =C21*D21 | F21: Every 12 months | G21: Amazon.ca | H21: Lead screw threads; apply monthly; keeps Z smooth and quiet
A22: Mobilgrease 28 1oz (or Nyogel 767A) | B22: Lubrication | C22: 1 | D22: 22 | E22: =C22*D22 | F22: Every 18–24 months | G22: Amazon.ca | H22: Premium rail grease; pack carriage block quarterly; small amount lasts long
A23: Brass Wire Nozzle Brush 2-pack | B23: Maintenance | C23: 1 | D23: 7 | E23: =C23*D23 | F23: Every 6 months | G23: Amazon.ca | H23: Replace when bristles flatten; never use steel brush on nozzle tip
A24: Nozzle Cleaning Needle Set 10-pack | B24: Maintenance | C24: 1 | D24: 9 | E24: =C24*D24 | F24: Every 12 months | G24: Amazon.ca | H24: Keep in toolbox at all times for quick clog clearing
A25: Silicone Thermal Paste 3g | B25: Maintenance | C25: 1 | D25: 8 | E25: =C25*D25 | F25: Every 12 months | G25: Amazon.ca | H25: Thermistor and heater cartridge heat transfer during hotend service
A26: FILAMENT DRYING & STORAGE
A27: Silica Gel 500g Orange Indicating ×3 bags | B27: Filament Storage | C27: 3 | D27: 14 | E27: =C27*D27 | F27: Every 12 months (rechargeable) | G27: Amazon.ca | H27: Orange→blue = saturated; recharge at 120°C for 2hrs; reuse indefinitely
A28: Vacuum Seal Bags + Pump 10-pack | B28: Filament Storage | C28: 1 | D28: 18 | E28: =C28*D28 | F28: Every 12 months | G28: Amazon.ca | H28: Seal opened spools for long-term storage; stack vertically on shelf
A29: Iris USA Airtight Container 12qt ×4 | B29: Filament Storage | C29: 4 | D29: 16 | E29: =C29*D29 | F29: As needed | G29: Amazon.ca | H29: 1 spool per container + silica; label with type and date opened
A30: Sunlu S2 Replacement Heating Pad | B30: Filament Storage | C30: 1 | D30: 22 | E30: =C30*D30 | F30: Every 24 months | G30: Amazon.ca | H30: Spare heating element; order when dryer fails to reach set temp
A31: Activated Carbon Media Refill 500g | B31: Filament Storage | C31: 1 | D31: 18 | E31: =C31*D31 | F31: Every 6 months | G31: Amazon.ca | H31: Refill for Nevermore and exhaust filter; replace when smell returns
A32: TOOLS
A33: Digital Calipers 150mm (Mitutoyo or Rexbeti) | B33: Tools | C33: 1 | D33: 38 | E33: =C33*D33 | F33: Every 3–5 years | G33: Amazon.ca | H33: First-print calibration; measure actual part dimensions vs model
A34: Feeler Gauge Set Metric + Imperial | B34: Tools | C34: 1 | D34: 12 | E34: =C34*D34 | F34: Every 5+ years | G34: Amazon.ca | H34: 0.15mm = standard nozzle-to-bed gap for paper-method leveling
A35: Hex Key Set Metric Long-Arm Ball-End | B35: Tools | C35: 1 | D35: 22 | E35: =C35*D35 | F35: Every 5+ years | G35: Amazon.ca | H35: M2–M5 hex keys for all printer assembly and maintenance
A36: Torque Screwdriver Set 0.5–5Nm | B36: Tools | C36: 1 | D36: 45 | E36: =C36*D36 | F36: Every 5+ years | G36: Amazon.ca | H36: Consistent nozzle torque (1–1.5Nm hot); prevents cracked heat blocks
A37: Flush Cutters ESD Safe | B37: Tools | C37: 1 | D37: 14 | E37: =C37*D37 | F37: Every 2–3 years | G37: Amazon.ca | H37: Support removal; zip tie trimming; ESD safe near electronics
A38: ESD Tweezers Set | B38: Tools | C38: 1 | D38: 16 | E38: =C38*D38 | F38: Every 3–5 years | G38: Amazon.ca | H38: Handling small parts; first-layer string removal while printing
A39: Heat Gun 300–600°C | B39: Tools | C39: 1 | D39: 35 | E39: =C39*D39 | F39: Every 5+ years | G39: Amazon.ca | H39: Heatset inserts; heat-shrink tubing; removing stuck prints
A40: Digital Multimeter (Fluke 115 or UNI-T UT61E) | B40: Tools | C40: 1 | D40: 65 | E40: =C40*D40 | F40: Every 5+ years | G40: Amazon.ca | H40: PSU voltage; continuity; thermistor resistance verification
...
