Workbook

Sheet Summary Dashboard
A1: Sensor Species Family — BOM Summary Dashboard
A2: Project: Sculptural / Kinetic Art & Sensing Installation | Currency: CAD (estimated) | Location: Whitehorse, YT | Date: 2026-05-15
A4: COST BREAKDOWN BY CATEGORY
A5: Category | B5: Total Cost (CAD est.) | C5: % of Grand Total
A6: 3D Printed Parts (Materials) | B6: =BOM!J22 | C6: =IF(B17=0,"",B6/B17)
A7: Filaments | B7: =BOM!J32 | C7: =IF(B17=0,"",B7/B17)
A8: Printer Upgrades & Fab Equipment | B8: =BOM!J45 | C8: =IF(B17=0,"",B8/B17)
A9: Mechanical Hardware | B9: =BOM!J64 | C9: =IF(B17=0,"",B9/B17)
A10: Wire, Cable & Tendons | B10: =BOM!J76 | C10: =IF(B17=0,"",B10/B17)
A11: Electronics — Sensors | B11: =BOM!J87 | C11: =IF(B17=0,"",B11/B17)
A12: Electronics — Controllers & Computing | B12: =BOM!J97 | C12: =IF(B17=0,"",B12/B17)
A13: Electronics — Power | B13: =BOM!J108 | C13: =IF(B17=0,"",B13/B17)
A14: Electronics — Lighting & Effects | B14: =BOM!J116 | C14: =IF(B17=0,"",B14/B17)
A15: Connectors & Wiring Accessories | B15: =BOM!J129 | C15: =IF(B17=0,"",B15/B17)
A16: Consumables & Workshop Supplies | B16: =BOM!J151 | C16: =IF(B17=0,"",B16/B17)
A17: GRAND TOTAL — All Categories | B17: =SUM(B6:B16)
A19: PROJECT STATS
A20: Metric | B20: Value
A21: Total Unique Line Items | B21: 106
A22: Critical Priority Items | B22: 57
A23: Recommended Priority Items | B23: =COUNTIF(BOM!L:L,"Recommended")
A24: Optional Priority Items | B24: =COUNTIF(BOM!L:L,"Optional")
A25: Items To Order | B25: =COUNTIF(BOM!M:M,"To Order")
A26: Items In Stock | B26: =COUNTIF(BOM!M:M,"In Stock")
A27: Items Ordered | B27: =COUNTIF(BOM!M:M,"Ordered")
A28: Estimated Grand Total (CAD) | B28: =B17
A30: PROJECT NOTES
A31: • All costs are CAD estimates as of May 2026; prices may vary by supplier and availability in Whitehorse, YT.
A32: • 3D printing filament costs are estimated at material cost only (electricity + machine wear not included).
A33: • Priority: CRITICAL = project cannot proceed without; RECOMMENDED = strongly advised; OPTIONAL = nice-to-have.
A34: • Status: 'To Order' items should be sourced first. Consider bulk fastener orders from Bolt Depot or Fastenal.
A35: • Whitehorse sourcing: Electronics may require online ordering (Adafruit, Digikey). Budget extra for shipping to YT.
A36: • Cross-reference BOM Item # against your 3D print job queue and assembly notes for each morphology sub-system.
A37: • PETG-CF and ASA filaments require hardened nozzle + enclosure — ensure printer upgrades are received first.
A38: • Sensor node count: 6× Pico W + 4× QT Py RP2040 + 1× RPi 4B central hub. Verify I2C address conflicts before assembly.

Sheet BOM
A1: Sensor Species Family — Full Bill of Materials
A2: Project: Sculptural / Kinetic Art & Sensing Installation | Currency: CAD (estimated) | Generated: 2026-05-15
A3: SECTION 1 — MORPHOLOGY COMPONENTS: 3D PRINTED PARTS
A4: Item # | B4: Component Name | C4: Description / Notes | D4: Category | E4: Morphology / Assembly | F4: Material or Spec | G4: Qty | H4: Unit | I4: Unit Cost (CAD est.) | J4: Total Cost (CAD) | K4: Supplier / Source | L4: Priority | M4: Status
A5: 1 | B5: Pollen Pod Shell | C5: Main sensor housing capsule — ovoid shell, two-part clamshell | D5: 3D Printed Parts | E5: Pollen Pod | F5: PETG or ABS, ~45g/pod | G5: 6 | H5: ea | I5: 3.5 | J5: =IF(G5="","",G5*I5) | K5: 3D Print in-house / Filament cost | L5: Critical | M5: To Order
A6: 2 | B6: Pollen Pod Vent Ring | C6: Parametric lattice insert for airflow/venting | D6: 3D Printed Parts | E6: Pollen Pod | F6: TPU 95A, ~8g each | G6: 6 | H6: ea | I6: 1.2 | J6: =IF(G6="","",G6*I6) | K6: 3D Print in-house / Filament cost | L6: Recommended | M6: To Order
A7: 3 | B7: Pollen Pod Mounting Flange | C7: M3 heat-set insert collar for pod attachment | D7: 3D Printed Parts | E7: Pollen Pod | F7: PETG, ~5g each | G7: 6 | H7: ea | I7: 0.8 | J7: =IF(G7="","",G7*I7) | K7: 3D Print in-house / Filament cost | L7: Critical | M7: To Order
A8: 4 | B8: Garland Link Body | C8: Articulating chain link body, oval form with pivot bore | D8: 3D Printed Parts | E8: Garland Links | F8: PETG, ~12g each | G8: 48 | H8: ea | I8: 0.9 | J8: =IF(G8="","",G8*I8) | K8: 3D Print in-house / Filament cost | L8: Critical | M8: To Order
A9: 5 | B9: Garland End Cap | C9: Capped terminus link with cable pass-through | D9: 3D Printed Parts | E9: Garland Links | F9: PETG, ~9g each | G9: 12 | H9: ea | I9: 0.8 | J9: =IF(G9="","",G9*I9) | K9: 3D Print in-house / Filament cost | L9: Critical | M9: To Order
A10: 6 | B10: Garland Spacer Ring | C10: Inter-link spacing washer | D10: 3D Printed Parts | E10: Garland Links | F10: TPU 85A, ~2g each | G10: 48 | H10: ea | I10: 0.3 | J10: =IF(G10="","",G10*I10) | K10: 3D Print in-house / Filament cost | L10: Recommended | M10: To Order
A11: 7 | B11: Tendon Routing Cleat | C11: Cable anchor with groove for tendon management | D11: 3D Printed Parts | E11: Tendons | F11: PETG, ~6g each | G11: 24 | H11: ea | I11: 0.7 | J11: =IF(G11="","",G11*I11) | K11: 3D Print in-house / Filament cost | L11: Critical | M11: To Order
A12: 8 | B12: Tendon Tensioner Body | C12: Spring-loaded adjuster housing for tendon tension | D12: 3D Printed Parts | E12: Tendons | F12: PETG, ~18g each | G12: 12 | H12: ea | I12: 1.6 | J12: =IF(G12="","",G12*I12) | K12: 3D Print in-house / Filament cost | L12: Critical | M12: To Order
A13: 9 | B13: Tendon Pulley Wheel | C13: Small flanged wheel, 8mm bore, for tendon routing | D13: 3D Printed Parts | E13: Tendons | F13: PETG or PLA, ~7g each | G13: 24 | H13: ea | I13: 0.7 | J13: =IF(G13="","",G13*I13) | K13: 3D Print in-house / Filament cost | L13: Critical | M13: To Order
A14: 10 | B14: Perch Pod Main Body | C14: Sensor nest / mounting platform | D14: 3D Printed Parts | E14: Perch Pods | F14: PETG, ~60g each | G14: 4 | H14: ea | I14: 4.5 | J14: =IF(G14="","",G14*I14) | K14: 3D Print in-house / Filament cost | L14: Critical | M14: To Order
A15: 11 | B15: Perch Pod Canopy | C15: Dome cover with diffuser aperture | D15: 3D Printed Parts | E15: Perch Pods | F15: Clear PETG or PETG-CF, ~22g | G15: 4 | H15: ea | I15: 2.2 | J15: =IF(G15="","",G15*I15) | K15: 3D Print in-house / Filament cost | L15: Critical | M15: To Order
A16: 12 | B16: Perch Pod Base Bracket | C16: Wall/rod mounting interface bracket | D16: 3D Printed Parts | E16: Perch Pods | F16: PETG, ~15g each | G16: 4 | H16: ea | I16: 1.4 | J16: =IF(G16="","",G16*I16) | K16: 3D Print in-house / Filament cost | L16: Critical | M16: To Order
... A21: 17 | B21: Drift Fin | C21: Thin curved stabilizer fin for hanging balance | D21: 3D Printed Parts | E21: Garland Extras | F21: PETG-CF, ~10g each | G21: 16 | H21: ea | I21: 1 | J21: =IF(G21="","",G21*I21) | K21: 3D Print in-house / Filament cost | L21: Optional | M21: To Order
A22: SUBTOTAL — 3D Printed Parts | J22: =SUM(J5:J21)
A24: SECTION 2 — FILAMENTS
A25: Item # | B25: Component Name | C25: Description / Notes | D25: Category | E25: Morphology / Assembly | F25: Material or Spec | G25: Qty | H25: Unit | I25: Unit Cost (CAD est.) | J25: Total Cost (CAD) | K25: Supplier / Source | L25: Priority | M25: Status
A26: 18 | B26: PETG Standard Filament | C26: Black, white, and natural/translucent — standard structural filament | D26: Filaments | E26: All Print Morphologies | F26: PETG 1.75mm 1kg spool | G26: 3 | H26: spool | I26: 34 | J26: =IF(G26="","",G26*I26) | K26: Prusa/MatterHackers/Amazon | L26: Critical | M26: To Order
A27: 19 | B27: TPU 95A Flexible Filament | C27: Black flexible filament for vent rings and edge trim | D27: Filaments | E27: Vent Rings / Edge Trim | F27: TPU 95A 1.75mm 0.5kg spool | G27: 2 | H27: spool | I27: 28 | J27: =IF(G27="","",G27*I27) | K27: Prusa/eSUN/Amazon | L27: Critical | M27: To Order
A28: 20 | B28: TPU 85A Ultra-Flex Filament | C28: Black ultra-flex for garland spacer rings | D28: Filaments | E28: Spacer Rings | F28: TPU 85A 1.75mm 0.5kg spool | G28: 1 | H28: spool | I28: 30 | J28: =IF(G28="","",G28*I28) | K28: Prusa/eSUN/Amazon | L28: Critical | M28: To Order
A29: 21 | B29: Clear PETG Filament | C29: Transparent — for canopy diffuser optics | D29: Filaments | E29: Perch Pod Canopy | F29: Clear PETG 1.75mm 1kg spool | G29: 1 | H29: spool | I29: 38 | J29: =IF(G29="","",G29*I29) | K29: Prusa/MatterHackers/Amazon | L29: Critical | M29: To Order
A30: 22 | B30: PETG-CF Carbon Fiber Filament | C30: Carbon fiber reinforced PETG for drift fins and structural parts | D30: Filaments | E30: Drift Fins / Rigid Parts | F30: PETG-CF 1.75mm 0.5kg spool | G30: 1 | H30: spool | I30: 55 | J30: =IF(G30="","",G30*I30) | K30: Prusa/Polymaker/Amazon | L30: Recommended | M30: To Order
A31: 23 | B31: ASA UV-Resistant Filament | C31: UV-stable outdoor-grade filament, grey or black | D31: Filaments | E31: Reef Plates | F31: ASA 1.75mm 1kg spool | G31: 1 | H31: spool | I31: 40 | J31: =IF(G31="","",G31*I31) | K31: Prusa/eSUN/Amazon | L31: Recommended | M31: To Order
A32: SUBTOTAL — Filaments | J32: =SUM(J26:J31)
A34: SECTION 3 — PRINTER UPGRADES & FABRICATION EQUIPMENT
A35: Item # | B35: Component Name | C35: Description / Notes | D35: Category | E35: Morphology / Assembly | F35: Material or Spec | G35: Qty | H35: Unit | I35: Unit Cost (CAD est.) | J35: Total Cost (CAD) | K35: Supplier / Source | L35: Priority | M35: Status
A36: 24 | B36: Hardened Steel Nozzle 0.4mm | C36: For carbon fiber filaments; resists abrasive wear | D36: Printer Upgrades | E36: Printer Hardware | F36: Hardened steel, 0.4mm | G36: 3 | H36: ea | I36: 12 | J36: =IF(G36="","",G36*I36) | K36: E3D / Trianglelab / Amazon | L36: Critical | M36: To Order
A37: 25 | B37: Hardened Steel Nozzle 0.6mm | C37: For faster structural prints; wider extrusion | D37: Printer Upgrades | E37: Printer Hardware | F37: Hardened steel, 0.6mm | G37: 2 | H37: ea | I37: 13 | J37: =IF(G37="","",G37*I37) | K37: E3D / Trianglelab / Amazon | L37: Recommended | M37: To Order
A38: 26 | B38: All-Metal Hotend Upgrade Kit | C38: For high-temp PETG/ASA printing up to 300°C | D38: Printer Upgrades | E38: Printer Hardware | F38: All-metal, 300°C rated | G38: 1 | H38: kit | I38: 55 | J38: =IF(G38="","",G38*I38) | K38: E3D / Micro Swiss / Amazon | L38: Critical | M38: To Order
A39: 27 | B39: Direct Drive Extruder Upgrade Kit | C39: Direct drive conversion for better flex-filament control | D39: Printer Upgrades | E39: Printer Hardware | F39: Direct drive kit | G39: 1 | H39: kit | I39: 75 | J39: =IF(G39="","",G39*I39) | K39: Bondtech / Trianglelab / Amazon | L39: Recommended | M39: To Order
A40: 28 | B40: PEI Spring Steel Magnetic Build Plate | C40: Magnetic flex plate with PEI surface, 235x235mm | D40: Printer Upgrades | E40: Printer Hardware | F40: PEI spring steel, 235x235mm | G40: 2 | H40: ea | I40: 28 | J40: =IF(G40="","",G40*I40) | K40: Prusa / Energetic / Amazon | L40: Recommended | M40: To Order
A41: 29 | B41: Filament Drybox w/ Humidity Control | C41: Active drybox for moisture-sensitive filaments (TPU, PA, CF) | D41: Printer Upgrades | E41: Fab Equipment | F41: Drybox with hygrometer | G41: 1 | H41: ea | I41: 45 | J41: =IF(G41="","",G41*I41) | K41: Sunlu / Eibos / Amazon | L41: Critical | M41: To Order
A42: 30 | B42: Filament Moisture Sensor/Hygrometer | C42: Monitor humidity in drybox/storage | D42: Printer Upgrades | E42: Fab Equipment | F42: Digital hygrometer | G42: 2 | H42: ea | I42: 12 | J42: =IF(G42="","",G42*I42) | K42: Amazon / local hardware | L42: Recommended | M42: To Order
A43: 31 | B43: PTFE Bowden Tube | C43: Replacement tube 4mm OD 2mm ID, 3m length | D43: Printer Upgrades | E43: Printer Hardware | F43: PTFE, 4mm OD / 2mm ID, 3m | G43: 1 | H43: length | I43: 8 | J43: =IF(G43="","",G43*I43) | K43: Capricorn / Amazon | L43: Recommended | M43: To Order
A44: 32 | B44: Printer Enclosure Kit/DIY Panels | C44: Enclosure for controlled printing environment — required for ASA | D44: Printer Upgrades | E44: Fab Equipment | F44: Enclosure panels or kit | G44: 1 | H44: kit | I44: 80 | J44: =IF(G44="","",G44*I44) | K44: IKEA Lack mod / Creality / DIY | L44: Critical | M44: To Order
A45: SUBTOTAL — Printer Upgrades & Fabrication Equipment | J45: =SUM(J36:J44)
A47: SECTION 4 — MECHANICAL HARDWARE: FASTENERS & STRUCTURAL
...
